#VRML_SIM R2023b utf8
# license: Apache License 2.0
# license url: http://www.apache.org/licenses/LICENSE-2.0
# This is a proto file for Webots for the LDPlatform
# Extracted from: /home/inmojang/workspace/lecture/assignment/ld90_ws/Omron_LD_ROS_Package/src/ld_visualisation/urdf/LD_90.urdf

PROTO LD90 [
  field  SFVec3f     translation     0 0 0
  field  SFRotation  rotation        0 0 1 0
  field  SFString    name            "LD90"  # Is `Robot.name`.
  field  SFString    controller      "void"        # Is `Robot.controller`.
  field  MFString    controllerArgs  []            # Is `Robot.controllerArgs`.
  field  SFString    customData      ""            # Is `Robot.customData`.
  field  SFBool      supervisor      FALSE         # Is `Robot.supervisor`.
  field  SFBool      synchronization TRUE          # Is `Robot.synchronization`.
  field  SFBool      selfCollision   FALSE         # Is `Robot.selfCollision`.
]
{
  Robot {
    translation IS translation
    rotation IS rotation
    name IS name
    controller IS controller
    controllerArgs IS controllerArgs
    customData IS customData
    supervisor IS supervisor
    synchronization IS synchronization
    selfCollision IS selfCollision
    children [
      Pose {
        rotation 0.577350 0.577350 0.577350 2.094395
        children [
          Shape {
            appearance DEF white PBRAppearance {
              baseColor 0.500000 0.500000 0.500000
              roughness 1.000000
              metalness 0
            }
            geometry DEF LD_Platform Mesh {
              url "./meshes/LD_Platform.STL"
            }
          }
        ]
      }
      HingeJoint { # Wheel - Left 
        jointParameters HingeJointParameters {
          axis 0.000000 1.000000 0.000000
          anchor 0.000000 0.196425 0.000881
        }
        device [
          RotationalMotor {
            name "left_wheel_joint"
            maxTorque 10000
          }
          PositionSensor {
            name "left_wheel_joint_sensor"
          }
        ]
        endPoint Solid {
          translation 0.000000 0.196425 0.000881
          rotation 1.000000 0.000000 0.000000 1.570796                        
          children [
            Shape {
              appearance DEF black PBRAppearance {
                baseColor 0.500000 0.500000 0.500000
                roughness 1.000000
                metalness 0
              }
              geometry Cylinder {
                radius 0.088
                height 0.03937
              }
            }
          ]
          name "left_wheel"
          boundingObject Cylinder {
            radius 0.088
            height 0.03937
          }
          physics Physics {
            density -1
            mass 0.170000
            centerOfMass [ 0.000000 0.000000 0.000000 ]
            inertiaMatrix [
              2.040000e-04 3.060000e-04 2.040000e-04
              0.000000e+00 0.000000e+00 0.000000e+00
            ]
          }
        }
      }
      HingeJoint { # Wheel - Right 
        jointParameters HingeJointParameters {
          axis 0.000000 -1.000000 0.000000
          anchor 0.000000 -0.196425 0.000881
        }
        device [
          RotationalMotor {
            name "right_wheel_joint"
            maxTorque 10000
          }
          PositionSensor {
            name "right_wheel_joint_sensor"
          }
        ]
        endPoint Solid {
          translation 0.000000 -0.196425 0.000881
          rotation 1.000000 0.000000 0.000000 1.570796
          children [
            Shape {
              appearance USE black
              geometry Cylinder {
                radius 0.088
                height 0.03937
              }
            }
          ]
          name "right_wheel"
          boundingObject Cylinder {
            radius 0.088
            height 0.03937
          }
          physics Physics {
            density -1
            mass 0.170000
            centerOfMass [ 0.000000 0.000000 0.000000 ]
            inertiaMatrix [
              2.040000e-04 3.060000e-04 2.040000e-04
              0.000000e+00 0.000000e+00 0.000000e+00
            ]
          }
        }
      }
      HingeJoint { # Caster - Right Front 
        jointParameters HingeJointParameters {
          axis 0.000000 -1.000000 0.000000
          anchor 0.209000 -0.108000 -0.049000
        }
        device [
          RotationalMotor {
            name "right_front_small_wheel_joint"
            maxTorque 10000
          }
          PositionSensor {
            name "right_front_small_wheel_joint_sensor"
          }
        ]
        endPoint Solid {
          translation 0.209000 -0.108000 -0.049000
          rotation 1.000000 0.000000 0.000000 1.570796          
          children [
            Shape {
              appearance USE black
              geometry Cylinder {
                radius 0.0375
                height 0.02775
              }
            }
          ]
          name "right_front_small_wheel"
          boundingObject Cylinder {
            radius 0.0375
            height 0.02775
          }
          physics Physics {
            density -1
            mass 0.170000
            centerOfMass [ 0.000000 0.000000 0.000000 ]
            inertiaMatrix [
              2.040000e-04 3.060000e-04 2.040000e-04
              0.000000e+00 0.000000e+00 0.000000e+00
            ]
          }
        }
      }
      HingeJoint { # Caster - Left Front
        jointParameters HingeJointParameters {
          axis 0.000000 1.000000 0.000000
          anchor 0.209000 0.108000 -0.049000
        }
        device [
          RotationalMotor {
            name "left_front_small_wheel_joint"
            maxTorque 10000
          }
          PositionSensor {
            name "left_front_small_wheel_joint_sensor"
          }
        ]
        endPoint Solid {
          translation 0.209000 0.108000 -0.049000
          rotation 1.000000 0.000000 0.000000 1.570796          
              
          children [
            Shape {
              appearance USE black
              geometry Cylinder {
                radius 0.0375
                height 0.02775
              }
            }
          ]

          name "left_front_small_wheel"
          boundingObject Cylinder {
            radius 0.0375
            height 0.02775
          }
          physics Physics {
            density -1
            mass 0.170000
            centerOfMass [ 0.000000 0.000000 0.000000 ]
            inertiaMatrix [
              2.040000e-04 3.060000e-04 2.040000e-04
              0.000000e+00 0.000000e+00 0.000000e+00
            ]
          }
        }
      }
      HingeJoint { # Caster - Left Rear
        jointParameters HingeJointParameters {
          axis 0.000000 1.000000 0.000000
          anchor -0.228000 0.156000 -0.049000
        }
        device [
          RotationalMotor {
            name "left_back_small_wheel_joint"
            maxTorque 10000
          }
          PositionSensor {
            name "left_back_small_wheel_joint_sensor"
          }
        ]
        endPoint Solid {
          translation -0.228000 0.156000 -0.049000
          rotation 1.000000 0.000000 0.000000 1.570796                        
          children [
            Shape {
              appearance USE black
              geometry Cylinder {
                radius 0.0375
                height 0.02775
              }
            }
          ]
          name "left_back_small_wheel"
          boundingObject Cylinder {
            radius 0.0375
            height 0.02775
          }
          physics Physics {
            density -1
            mass 0.170000
            centerOfMass [ 0.000000 0.000000 0.000000 ]
            inertiaMatrix [
              2.040000e-04 3.060000e-04 2.040000e-04
              0.000000e+00 0.000000e+00 0.000000e+00
            ]
          }
        }
      }
      HingeJoint { # Caster - Right Rear
        jointParameters HingeJointParameters {
          axis 0.000000 -1.000000 0.000000
          anchor -0.228000 -0.156000 -0.049000
        }
        device [
          RotationalMotor {
            name "right_back_small_wheel_joint"
            maxTorque 10000
          }
          PositionSensor {
            name "right_back_small_wheel_joint_sensor"
          }
        ]
        endPoint Solid {
          translation -0.228000 -0.156000 -0.049000
          rotation 1.000000 0.000000 0.000000 1.570796          
          children [
            Shape {
              appearance USE black
              geometry Cylinder {
                radius 0.0375
                height 0.02775
              }
            }
          ]
          name "right_back_small_wheel"
          boundingObject Cylinder {
            radius 0.0375
            height 0.02775
          }
          physics Physics {
            density -1
            mass 0.170000
            centerOfMass [ 0.000000 0.000000 0.000000 ]
            inertiaMatrix [
              2.040000e-04 3.060000e-04 2.040000e-04
              0.000000e+00 0.000000e+00 0.000000e+00
            ]
          }
        }
      }
    ]
    # boundingObject Pose {
    #   rotation 0.577350 0.577350 0.577350 2.094395
    #   children [
    #     USE LD_Platform
    #   ]
    # }   
    physics Physics {
      density -1
      mass 4.070000
      centerOfMass [ 0.000000 0.000000 0.000000 ]
      inertiaMatrix [
        4.260000e-01 4.960000e-01 9.100000e-01
        0.000000e+00 0.000000e+00 0.000000e+00
      ]
    }    
  }
}
