#VRML_SIM R2023b utf8

PROTO SalusSuite [
]
{
    SliderJoint { # Wheel - Left
        jointParameters JointParameters {
            axis 0.000000 0.000000 1.000000
        }
        device [
            LinearMotor {
                name "mast_joint"
                maxPosition 5.00
                maxForce 10000
            }
            PositionSensor {
                name "mast_joint_sensor"
            }
        ]
        endPoint Solid {
            children [
                DEF RICOH_THETA Camera {
                    translation 0 0 1.0
                    rotation 0 0 1 1.5708 # z-axis 90 degree
                    name "camera_360"
                    width 1280
                    height 800 
                    projection "cylindrical"
                    fieldOfView 6.2832
                    children [
                        Shape {
                            appearance PBRAppearance {
                            baseColor 0.5 0.5 0.5
                            roughness 1
                            metalness 1
                            }
                            geometry Box {
                            size 0.029 0.0517 0.1362 # Ricoh Theta Spec: 29.0 mm (D) x 51.7 mm(W) x 136.2 mm (H) 
                            }
                        }         
                    ]         
                }
            ]
        }
    }
}